Workbook

Sheet input
B1: Kniha analýz | C1: Popis vzorku | D1: ID měření | E1: Objem [l] | F1: Hmotnost [kg] | G1: Referenční datum | H1: LabSyS laboratoř | I1: Ra | J1: Ra_err | K1: K | L1: K_err | M1: Th | N1: Th_err | O1: Index | P1: Index_err | R1: sample_name | S1: Ra | T1: Ra_err | U1: K | V1: K_err | W1: Th | X1: Th_err | Y1: Index | Z1: Index_err
B2: 3666-2024 | C2: Struska/škvára | D2: 3666-2024-4 | E2: 1 | F2: 1.011 | G2: 45574 | I2: =IF($D2="","",_xlfn.xlookup($D2,$R:$R,$S:$S,"")) -> 65.266179 | J2: =IF($D2="","",_xlfn.xlookup($D2,$R:$R,$T:$T,"")) -> 0.13556479 | K2: =IF($D2="","",_xlfn.xlookup($D2,$R:$R,$U:$U,"")) -> 160.72712 | L2: =IF($D2="","",_xlfn.xlookup($D2,$R:$R,$V:$V,"")) -> 1.2151718 | M2: =IF($D2="","",_xlfn.xlookup($D2,$R:$R,$W:$W,"")) -> 63.930664 | N2: =IF($D2="","",_xlfn.xlookup($D2,$R:$R,$X:$X,"")) -> 0.081980446 | O2: =IF($D2="","",_xlfn.xlookup($D2,$R:$R,$Y:$Y,"")) -> 0.59078295 | P2: =IF($D2="","",_xlfn.xlookup($D2,$R:$R,$Z:$Z,"")) -> 0.00073231764 | R2: 4794-2024-3 | S2: 42.023525 | T2: 0.16863224 | U2: 851.59364 | V2: 2.0035609 | W2: 53.215803 | X2: 0.088102939 | Y2: 0.69002198 | Z2: 0.00097777629
B3: 3667-2024 | C3: Popílek | D3: 3667-2024-4 | E3: 1 | F3: 0.926 | G3: 45572 | I3: =IF($D3="","",_xlfn.xlookup($D3,$R:$R,$S:$S,"")) -> 69.417567 | J3: =IF($D3="","",_xlfn.xlookup($D3,$R:$R,$T:$T,"")) -> 0.17533443 | K3: =IF($D3="","",_xlfn.xlookup($D3,$R:$R,$U:$U,"")) -> 169.0155 | L3: =IF($D3="","",_xlfn.xlookup($D3,$R:$R,$V:$V,"")) -> 1.8358342 | M3: =IF($D3="","",_xlfn.xlookup($D3,$R:$R,$W:$W,"")) -> 66.068438 | N3: =IF($D3="","",_xlfn.xlookup($D3,$R:$R,$X:$X,"")) -> 0.10603044 | O3: =IF($D3="","",_xlfn.xlookup($D3,$R:$R,$Y:$Y,"")) -> 0.61807258 | P3: =IF($D3="","",_xlfn.xlookup($D3,$R:$R,$Z:$Z,"")) -> 0.00099855763 | R3: 4787-2024-3 | S3: 52.876986 | T3: 0.24570299 | U3: 903.62575 | V3: 2.5786431 | W3: 68.061999 | X3: 0.12836902 | Y3: 0.8177752 | Z3: 0.0013496535
B4: 3668-2024 | C4: Litý granulát | D4: 3668-2024-4 | E4: 1 | F4: 0.948 | G4: 45574 | I4: =IF($D4="","",_xlfn.xlookup($D4,$R:$R,$S:$S,"")) -> #NAME? | J4: =IF($D4="","",_xlfn.xlookup($D4,$R:$R,$T:$T,"")) -> #NAME? | K4: =IF($D4="","",_xlfn.xlookup($D4,$R:$R,$U:$U,"")) -> #NAME? | L4: =IF($D4="","",_xlfn.xlookup($D4,$R:$R,$V:$V,"")) -> #NAME? | M4: =IF($D4="","",_xlfn.xlookup($D4,$R:$R,$W:$W,"")) -> #NAME? | N4: =IF($D4="","",_xlfn.xlookup($D4,$R:$R,$X:$X,"")) -> #NAME? | O4: =IF($D4="","",_xlfn.xlookup($D4,$R:$R,$Y:$Y,"")) -> #NAME? | P4: =IF($D4="","",_xlfn.xlookup($D4,$R:$R,$Z:$Z,"")) -> #NAME? | R4: 4724-2024-3 | S4: 95.500001 | T4: 0.35153688 | U4: 793.49365 | V4: 2.6627145 | W4: 83.651268 | X4: 0.18366258 | Y4: 1.0010876 | Z4: 0.0017332549
B5: 3962-2024 | C5: Popílek a směsi s popílkem | D5: 3962-2024-4 | E5: 1 | F5: 0.893 | G5: 45590 | I5: =IF($D5="","",_xlfn.xlookup($D5,$R:$R,$S:$S,"")) -> #NAME? | J5: =IF($D5="","",_xlfn.xlookup($D5,$R:$R,$T:$T,"")) -> #NAME? | K5: =IF($D5="","",_xlfn.xlookup($D5,$R:$R,$U:$U,"")) -> #NAME? | L5: =IF($D5="","",_xlfn.xlookup($D5,$R:$R,$V:$V,"")) -> #NAME? | M5: =IF($D5="","",_xlfn.xlookup($D5,$R:$R,$W:$W,"")) -> #NAME? | N5: =IF($D5="","",_xlfn.xlookup($D5,$R:$R,$X:$X,"")) -> #NAME? | O5: =IF($D5="","",_xlfn.xlookup($D5,$R:$R,$Y:$Y,"")) -> #NAME? | P5: =IF($D5="","",_xlfn.xlookup($D5,$R:$R,$Z:$Z,"")) -> #NAME? | R5: 4723-2024-3 | S5: 78.191888 | T5: 0.25991286 | U5: 840.93573 | V5: 2.1497122 | W5: 69.256868 | X5: 0.13579305 | Y5: 0.88723588 | Z5: 0.0013134212
B6: 3964-2024 | C6: Popílek a směsi s popílkem | D6: 3964-2024-4 | E6: 1 | F6: 0.989 | G6: 45594 | I6: =IF($D6="","",_xlfn.xlookup($D6,$R:$R,$S:$S,"")) -> #NAME? | J6: =IF($D6="","",_xlfn.xlookup($D6,$R:$R,$T:$T,"")) -> #NAME? | K6: =IF($D6="","",_xlfn.xlookup($D6,$R:$R,$U:$U,"")) -> #NAME? | L6: =IF($D6="","",_xlfn.xlookup($D6,$R:$R,$V:$V,"")) -> #NAME? | M6: =IF($D6="","",_xlfn.xlookup($D6,$R:$R,$W:$W,"")) -> #NAME? | N6: =IF($D6="","",_xlfn.xlookup($D6,$R:$R,$X:$X,"")) -> #NAME? | O6: =IF($D6="","",_xlfn.xlookup($D6,$R:$R,$Y:$Y,"")) -> #NAME? | P6: =IF($D6="","",_xlfn.xlookup($D6,$R:$R,$Z:$Z,"")) -> #NAME? | R6: 4720-2024-3 | S6: 54.921705 | T6: 0.23761629 | U6: 833.5932 | V6: 2.0454831 | W6: 54.104593 | X6: 0.12414407 | Y6: 0.73145971 | Z6: 0.0012155381
B7: 4249-2024 | C7: Struska (VEP) | D7: 4249-2024-4 | E7: 1 | F7: 0.676 | G7: 45616 | I7: =IF($D7="","",_xlfn.xlookup($D7,$R:$R,$S:$S,"")) -> #NAME? | J7: =IF($D7="","",_xlfn.xlookup($D7,$R:$R,$T:$T,"")) -> #NAME? | K7: =IF($D7="","",_xlfn.xlookup($D7,$R:$R,$U:$U,"")) -> #NAME? | L7: =IF($D7="","",_xlfn.xlookup($D7,$R:$R,$V:$V,"")) -> #NAME? | M7: =IF($D7="","",_xlfn.xlookup($D7,$R:$R,$W:$W,"")) -> #NAME? | N7: =IF($D7="","",_xlfn.xlookup($D7,$R:$R,$X:$X,"")) -> #NAME? | O7: =IF($D7="","",_xlfn.xlookup($D7,$R:$R,$Y:$Y,"")) -> #NAME? | P7: =IF($D7="","",_xlfn.xlookup($D7,$R:$R,$Z:$Z,"")) -> #NAME? | R7: 4607-2024-4 | S7: 56.326647 | T7: 0.17335495 | U7: 195.64359 | V7: 1.1868142 | W7: 45.903433 | X7: 0.090570345 | Y7: 0.48248719 | Z7: 0.00083395935
B8: 4250-2024 | C8: sádrovec (VEP) | D8: 4250-2024-4 | E8: 1 | F8: 1.29 | G8: 45616 | I8: =IF($D8="","",_xlfn.xlookup($D8,$R:$R,$S:$S,"")) -> #NAME? | J8: =IF($D8="","",_xlfn.xlookup($D8,$R:$R,$T:$T,"")) -> #NAME? | K8: =IF($D8="","",_xlfn.xlookup($D8,$R:$R,$U:$U,"")) -> #NAME? | L8: =IF($D8="","",_xlfn.xlookup($D8,$R:$R,$V:$V,"")) -> #NAME? | M8: =IF($D8="","",_xlfn.xlookup($D8,$R:$R,$W:$W,"")) -> #NAME? | N8: =IF($D8="","",_xlfn.xlookup($D8,$R:$R,$X:$X,"")) -> #NAME? | O8: =IF($D8="","",_xlfn.xlookup($D8,$R:$R,$Y:$Y,"")) -> #NAME? | P8: =IF($D8="","",_xlfn.xlookup($D8,$R:$R,$Z:$Z,"")) -> #NAME? | R8: 4457-2024-4 | S8: 72.20866 | T8: 0.1955454 | U8: 176.5784 | V8: 1.2483334 | W8: 65.051462 | X8: 0.10216388 | Y8: 0.62481231 | Z8: 0.00092679644
B9: 4251-2024 | C9: Aglomerát (VEP z popílku) | D9: 4251-2024-4 | E9: 1 | F9: 0.888 | G9: 45617 | I9: =IF($D9="","",_xlfn.xlookup($D9,$R:$R,$S:$S,"")) -> #NAME? | J9: =IF($D9="","",_xlfn.xlookup($D9,$R:$R,$T:$T,"")) -> #NAME? | K9: =IF($D9="","",_xlfn.xlookup($D9,$R:$R,$U:$U,"")) -> #NAME? | L9: =IF($D9="","",_xlfn.xlookup($D9,$R:$R,$V:$V,"")) -> #NAME? | M9: =IF($D9="","",_xlfn.xlookup($D9,$R:$R,$W:$W,"")) -> #NAME? | N9: =IF($D9="","",_xlfn.xlookup($D9,$R:$R,$X:$X,"")) -> #NAME? | O9: =IF($D9="","",_xlfn.xlookup($D9,$R:$R,$Y:$Y,"")) -> #NAME? | P9: =IF($D9="","",_xlfn.xlookup($D9,$R:$R,$Z:$Z,"")) -> #NAME? | R9: 4301-2025-2 | S9: 135.43118 | T9: 0.29532813 | U9: 408.64419 | V9: 2.3377209 | W9: 79.214719 | X9: 0.15429598 | Y9: 0.9837256 | Z9: 0.0014735988
B10: 4457-2024 | C10: Stabilizát | D10: 4457-2024-4 | E10: 1 | F10: 1.167 | G10: 45630 | I10: =IF($D10="","",_xlfn.xlookup($D10,$R:$R,$S:$S,"")) -> #NAME? | J10: =IF($D10="","",_xlfn.xlookup($D10,$R:$R,$T:$T,"")) -> #NAME? | K10: =IF($D10="","",_xlfn.xlookup($D10,$R:$R,$U:$U,"")) -> #NAME? | L10: =IF($D10="","",_xlfn.xlookup($D10,$R:$R,$V:$V,"")) -> #NAME? | M10: =IF($D10="","",_xlfn.xlookup($D10,$R:$R,$W:$W,"")) -> #NAME? | N10: =IF($D10="","",_xlfn.xlookup($D10,$R:$R,$X:$X,"")) -> #NAME? | O10: =IF($D10="","",_xlfn.xlookup($D10,$R:$R,$Y:$Y,"")) -> #NAME? | P10: =IF($D10="","",_xlfn.xlookup($D10,$R:$R,$Z:$Z,"")) -> #NAME? | R10: 4271-2025-3 | S10: 111.68142 | T10: 0.22355813 | U10: 182.91843 | V10: 1.9882033 | W10: 83.030023 | X10: 0.1167993 | Y10: 0.84839432 | Z10: 0.0011556741
B11: 4605-2024 | C11: Stabilizát | D11: 4605-2024-4 | E11: 1 | F11: 0.97 | G11: 45639 | I11: =IF($D11="","",_xlfn.xlookup($D11,$R:$R,$S:$S,"")) -> #NAME? | J11: =IF($D11="","",_xlfn.xlookup($D11,$R:$R,$T:$T,"")) -> #NAME? | K11: =IF($D11="","",_xlfn.xlookup($D11,$R:$R,$U:$U,"")) -> #NAME? | L11: =IF($D11="","",_xlfn.xlookup($D11,$R:$R,$V:$V,"")) -> #NAME? | M11: =IF($D11="","",_xlfn.xlookup($D11,$R:$R,$W:$W,"")) -> #NAME? | N11: =IF($D11="","",_xlfn.xlookup($D11,$R:$R,$X:$X,"")) -> #NAME? | O11: =IF($D11="","",_xlfn.xlookup($D11,$R:$R,$Y:$Y,"")) -> #NAME? | P11: =IF($D11="","",_xlfn.xlookup($D11,$R:$R,$Z:$Z,"")) -> #NAME? | R11: 4251-2024-4 | S11: 80.365807 | T11: 0.19767031 | U11: 117.73906 | V11: 1.626496 | W11: 64.467232 | X11: 0.10327406 | Y11: 0.62946853 | Z11: 0.00099736257
B12: 4607-2024 | C12: Úletový popílek | D12: 4607-2024-4 | E12: 1 | F12: 0.697 | G12: 45637 | I12: =IF($D12="","",_xlfn.xlookup($D12,$R:$R,$S:$S,"")) -> #NAME? | J12: =IF($D12="","",_xlfn.xlookup($D12,$R:$R,$T:$T,"")) -> #NAME? | K12: =IF($D12="","",_xlfn.xlookup($D12,$R:$R,$U:$U,"")) -> #NAME? | L12: =IF($D12="","",_xlfn.xlookup($D12,$R:$R,$V:$V,"")) -> #NAME? | M12: =IF($D12="","",_xlfn.xlookup($D12,$R:$R,$W:$W,"")) -> #NAME? | N12: =IF($D12="","",_xlfn.xlookup($D12,$R:$R,$X:$X,"")) -> #NAME? | O12: =IF($D12="","",_xlfn.xlookup($D12,$R:$R,$Y:$Y,"")) -> #NAME? | P12: =IF($D12="","",_xlfn.xlookup($D12,$R:$R,$Z:$Z,"")) -> #NAME? | R12: 4249-2024-4 | S12: 60.938512 | T12: 0.224858 | U12: 130.68243 | V12: 1.6300245 | W12: 56.652565 | X12: 0.11747843 | Y12: 0.52995201 | Z12: 0.0010963757
B13: 4720-2024 | C13: taška | D13: 4720-2024-3 | E13: 1 | F13: 1.369 | G13: 45616 | I13: =IF($D13="","",_xlfn.xlookup($D13,$R:$R,$S:$S,"")) -> #NAME? | J13: =IF($D13="","",_xlfn.xlookup($D13,$R:$R,$T:$T,"")) -> #NAME? | K13: =IF($D13="","",_xlfn.xlookup($D13,$R:$R,$U:$U,"")) -> #NAME? | L13: =IF($D13="","",_xlfn.xlookup($D13,$R:$R,$V:$V,"")) -> #NAME? | M13: =IF($D13="","",_xlfn.xlookup($D13,$R:$R,$W:$W,"")) -> #NAME? | N13: =IF($D13="","",_xlfn.xlookup($D13,$R:$R,$X:$X,"")) -> #NAME? | O13: =IF($D13="","",_xlfn.xlookup($D13,$R:$R,$Y:$Y,"")) -> #NAME? | P13: =IF($D13="","",_xlfn.xlookup($D13,$R:$R,$Z:$Z,"")) -> #NAME? | R13: 4183-2025-3 | S13: 145.86759 | T13: 0.36242746 | U13: 420.98869 | V13: 2.6502032 | W13: 113.71461 | X13: 0.18935243 | Y13: 1.1951279 | Z13: 0.0017709436
... B16: 4787-2024 | C16: cihla | D16: 4787-2024-3 | E16: 1 | F16: 1.318 | G16: 45610 | I16: =IF($D16="","",_xlfn.xlookup($D16,$R:$R,$S:$S,"")) -> #NAME? | J16: =IF($D16="","",_xlfn.xlookup($D16,$R:$R,$T:$T,"")) -> #NAME? | K16: =IF($D16="","",_xlfn.xlookup($D16,$R:$R,$U:$U,"")) -> #NAME? | L16: =IF($D16="","",_xlfn.xlookup($D16,$R:$R,$V:$V,"")) -> #NAME? | M16: =IF($D16="","",_xlfn.xlookup($D16,$R:$R,$W:$W,"")) -> #NAME? | N16: =IF($D16="","",_xlfn.xlookup($D16,$R:$R,$X:$X,"")) -> #NAME? | O16: =IF($D16="","",_xlfn.xlookup($D16,$R:$R,$Y:$Y,"")) -> #NAME? | P16: =IF($D16="","",_xlfn.xlookup($D16,$R:$R,$Z:$Z,"")) -> #NAME? | R16: 3964-2024-4 | S16: 115.69007 | T16: 0.25787551 | U16: 351.6837 | V16: 2.3197972 | W16: 92.471487 | X16: 0.15594572 | Y16: 0.96521891 | Z16: 0.001394562
B17: 4788-2024 | C17: cihla | D17: NE | E17: 1 | G17: 45614 | I17: =IF($D17="","",_xlfn.xlookup($D17,$R:$R,$S:$S,"")) -> #NAME? | J17: =IF($D17="","",_xlfn.xlookup($D17,$R:$R,$T:$T,"")) -> #NAME? | K17: =IF($D17="","",_xlfn.xlookup($D17,$R:$R,$U:$U,"")) -> #NAME? | L17: =IF($D17="","",_xlfn.xlookup($D17,$R:$R,$V:$V,"")) -> #NAME? | M17: =IF($D17="","",_xlfn.xlookup($D17,$R:$R,$W:$W,"")) -> #NAME? | N17: =IF($D17="","",_xlfn.xlookup($D17,$R:$R,$X:$X,"")) -> #NAME? | O17: =IF($D17="","",_xlfn.xlookup($D17,$R:$R,$Y:$Y,"")) -> #NAME? | P17: =IF($D17="","",_xlfn.xlookup($D17,$R:$R,$Z:$Z,"")) -> #NAME? | R17: 3962-2024-4 | S17: 65.629116 | T17: 0.18755629 | U17: 239.37392 | V17: 1.7517688 | W17: 58.184146 | X17: 0.1134214 | Y17: 0.58947576 | Z17: 0.0010263703
B18: 4794-2024 | C18: nepálená cihla | D18: 4794-2024-3 | E18: 1 | F18: 1.27 | G18: 45611 | I18: =IF($D18="","",_xlfn.xlookup($D18,$R:$R,$S:$S,"")) -> #NAME? | J18: =IF($D18="","",_xlfn.xlookup($D18,$R:$R,$T:$T,"")) -> #NAME? | K18: =IF($D18="","",_xlfn.xlookup($D18,$R:$R,$U:$U,"")) -> #NAME? | L18: =IF($D18="","",_xlfn.xlookup($D18,$R:$R,$V:$V,"")) -> #NAME? | M18: =IF($D18="","",_xlfn.xlookup($D18,$R:$R,$W:$W,"")) -> #NAME? | N18: =IF($D18="","",_xlfn.xlookup($D18,$R:$R,$X:$X,"")) -> #NAME? | O18: =IF($D18="","",_xlfn.xlookup($D18,$R:$R,$Y:$Y,"")) -> #NAME? | P18: =IF($D18="","",_xlfn.xlookup($D18,$R:$R,$Z:$Z,"")) -> #NAME? | R18: 3954-2025-3 | S18: 109.85848 | T18: 0.21146678 | U18: 401.40467 | V18: 2.0655063 | W18: 65.714451 | X18: 0.12788085 | Y18: 0.82856875 | Z18: 0.0011746241
B19: 4797-2024 | C19: lisované vláknocementové desky | D19: 4797-2024-3 | E19: 1 | F19: 0.702 | G19: 45610 | I19: =IF($D19="","",_xlfn.xlookup($D19,$R:$R,$S:$S,"")) -> #NAME? | J19: =IF($D19="","",_xlfn.xlookup($D19,$R:$R,$T:$T,"")) -> #NAME? | K19: =IF($D19="","",_xlfn.xlookup($D19,$R:$R,$U:$U,"")) -> #NAME? | L19: =IF($D19="","",_xlfn.xlookup($D19,$R:$R,$V:$V,"")) -> #NAME? | M19: =IF($D19="","",_xlfn.xlookup($D19,$R:$R,$W:$W,"")) -> #NAME? | N19: =IF($D19="","",_xlfn.xlookup($D19,$R:$R,$X:$X,"")) -> #NAME? | O19: =IF($D19="","",_xlfn.xlookup($D19,$R:$R,$Y:$Y,"")) -> #NAME? | P19: =IF($D19="","",_xlfn.xlookup($D19,$R:$R,$Z:$Z,"")) -> #NAME? | R19: 3876-2025-3 | S19: 67.622267 | T19: 0.16537933 | U19: 172.08119 | V19: 1.2886105 | W19: 63.258716 | X19: 0.10001027 | Y19: 0.59906154 | Z19: 0.00085932863
B20: 59-2025 | C20: C 20/25 X0, XC1-2, S3 | D20: 59-2025-3 | E20: 1 | F20: 1.76 | G20: 45588 | I20: =IF($D20="","",_xlfn.xlookup($D20,$R:$R,$S:$S,"")) -> #NAME? | J20: =IF($D20="","",_xlfn.xlookup($D20,$R:$R,$T:$T,"")) -> #NAME? | K20: =IF($D20="","",_xlfn.xlookup($D20,$R:$R,$U:$U,"")) -> #NAME? | L20: =IF($D20="","",_xlfn.xlookup($D20,$R:$R,$V:$V,"")) -> #NAME? | M20: =IF($D20="","",_xlfn.xlookup($D20,$R:$R,$W:$W,"")) -> #NAME? | N20: =IF($D20="","",_xlfn.xlookup($D20,$R:$R,$X:$X,"")) -> #NAME? | O20: =IF($D20="","",_xlfn.xlookup($D20,$R:$R,$Y:$Y,"")) -> #NAME? | P20: =IF($D20="","",_xlfn.xlookup($D20,$R:$R,$Z:$Z,"")) -> #NAME? | R20: 3874-2025-3 | S20: 75.353513 | T20: 0.17281762 | U20: 186.6478 | V20: 1.3612161 | W20: 73.496642 | X20: 0.10450844 | Y20: 0.68087752 | Z20: 0.00090042926
B21: 60-2025 | C21: C 16/20, X0, XC1-2, S3 Dmax22 | D21: 60-2025-3 | E21: 1 | F21: 1.682 | G21: 45610 | I21: =IF($D21="","",_xlfn.xlookup($D21,$R:$R,$S:$S,"")) -> #NAME? | J21: =IF($D21="","",_xlfn.xlookup($D21,$R:$R,$T:$T,"")) -> #NAME? | K21: =IF($D21="","",_xlfn.xlookup($D21,$R:$R,$U:$U,"")) -> #NAME? | L21: =IF($D21="","",_xlfn.xlookup($D21,$R:$R,$V:$V,"")) -> #NAME? | M21: =IF($D21="","",_xlfn.xlookup($D21,$R:$R,$W:$W,"")) -> #NAME? | N21: =IF($D21="","",_xlfn.xlookup($D21,$R:$R,$X:$X,"")) -> #NAME? | O21: =IF($D21="","",_xlfn.xlookup($D21,$R:$R,$Y:$Y,"")) -> #NAME? | P21: =IF($D21="","",_xlfn.xlookup($D21,$R:$R,$Z:$Z,"")) -> #NAME? | R21: 3838-2025-2 | S21: 51.478938 | T21: 0.29926427 | U21: 915.36316 | V21: 2.5135483 | W21: 55.281028 | X21: 0.18097486 | Y21: 0.75312265 | Z21: 0.0015861558
B22: 145-2025 | C22: Balkánská rula, vzorek č. 1 | D22: 145-2025-2 | E22: 1 | F22: 1.821 | G22: 45672 | I22: =IF($D22="","",_xlfn.xlookup($D22,$R:$R,$S:$S,"")) -> #NAME? | J22: =IF($D22="","",_xlfn.xlookup($D22,$R:$R,$T:$T,"")) -> #NAME? | K22: =IF($D22="","",_xlfn.xlookup($D22,$R:$R,$U:$U,"")) -> #NAME? | L22: =IF($D22="","",_xlfn.xlookup($D22,$R:$R,$V:$V,"")) -> #NAME? | M22: =IF($D22="","",_xlfn.xlookup($D22,$R:$R,$W:$W,"")) -> #NAME? | N22: =IF($D22="","",_xlfn.xlookup($D22,$R:$R,$X:$X,"")) -> #NAME? | O22: =IF($D22="","",_xlfn.xlookup($D22,$R:$R,$Y:$Y,"")) -> #NAME? | P22: =IF($D22="","",_xlfn.xlookup($D22,$R:$R,$Z:$Z,"")) -> #NAME? | R22: 3668-2024-4 | S22: 63.664718 | T22: 0.15584943 | U22: 182.17377 | V22: 1.7896456 | W22: 57.198444 | X22: 0.094247228 | Y22: 0.55893254 | Z22: 0.00092076703
B23: 146-2025 | C23: balkánská rula | D23: 146-2025-3 | E23: 1 | F23: 1.849 | G23: 45672 | I23: =IF($D23="","",_xlfn.xlookup($D23,$R:$R,$S:$S,"")) -> #NAME? | J23: =IF($D23="","",_xlfn.xlookup($D23,$R:$R,$T:$T,"")) -> #NAME? | K23: =IF($D23="","",_xlfn.xlookup($D23,$R:$R,$U:$U,"")) -> #NAME? | L23: =IF($D23="","",_xlfn.xlookup($D23,$R:$R,$V:$V,"")) -> #NAME? | M23: =IF($D23="","",_xlfn.xlookup($D23,$R:$R,$W:$W,"")) -> #NAME? | N23: =IF($D23="","",_xlfn.xlookup($D23,$R:$R,$X:$X,"")) -> #NAME? | O23: =IF($D23="","",_xlfn.xlookup($D23,$R:$R,$Y:$Y,"")) -> #NAME? | P23: =IF($D23="","",_xlfn.xlookup($D23,$R:$R,$Z:$Z,"")) -> #NAME? | R23: 3667-2024-4 | S23: 69.417567 | T23: 0.17533443 | U23: 169.0155 | V23: 1.8358342 | W23: 66.068438 | X23: 0.10603044 | Y23: 0.61807258 | Z23: 0.00099855763
B24: 230-2025 | C24: škvára | D24: 230-2025-3 | E24: 1 | F24: 0.857 | G24: 45681 | I24: =IF($D24="","",_xlfn.xlookup($D24,$R:$R,$S:$S,"")) -> #NAME? | J24: =IF($D24="","",_xlfn.xlookup($D24,$R:$R,$T:$T,"")) -> #NAME? | K24: =IF($D24="","",_xlfn.xlookup($D24,$R:$R,$U:$U,"")) -> #NAME? | L24: =IF($D24="","",_xlfn.xlookup($D24,$R:$R,$V:$V,"")) -> #NAME? | M24: =IF($D24="","",_xlfn.xlookup($D24,$R:$R,$W:$W,"")) -> #NAME? | N24: =IF($D24="","",_xlfn.xlookup($D24,$R:$R,$X:$X,"")) -> #NAME? | O24: =IF($D24="","",_xlfn.xlookup($D24,$R:$R,$Y:$Y,"")) -> #NAME? | P24: =IF($D24="","",_xlfn.xlookup($D24,$R:$R,$Z:$Z,"")) -> #NAME? | R24: 3666-2024-4 | S24: 65.266179 | T24: 0.13556479 | U24: 160.72712 | V24: 1.2151718 | W24: 63.930664 | X24: 0.081980446 | Y24: 0.59078295 | Z24: 0.00073231764
B25: 235-2025 | C25: surový jíl | D25: 235-2025-3 | E25: 1 | F25: 0.987 | G25: 45642 | I25: =IF($D25="","",_xlfn.xlookup($D25,$R:$R,$S:$S,"")) -> #NAME? | J25: =IF($D25="","",_xlfn.xlookup($D25,$R:$R,$T:$T,"")) -> #NAME? | K25: =IF($D25="","",_xlfn.xlookup($D25,$R:$R,$U:$U,"")) -> #NAME? | L25: =IF($D25="","",_xlfn.xlookup($D25,$R:$R,$V:$V,"")) -> #NAME? | M25: =IF($D25="","",_xlfn.xlookup($D25,$R:$R,$W:$W,"")) -> #NAME? | N25: =IF($D25="","",_xlfn.xlookup($D25,$R:$R,$X:$X,"")) -> #NAME? | O25: =IF($D25="","",_xlfn.xlookup($D25,$R:$R,$Y:$Y,"")) -> #NAME? | P25: =IF($D25="","",_xlfn.xlookup($D25,$R:$R,$Z:$Z,"")) -> #NAME? | R25: 3608-2025-3 | S25: 22.446542 | T25: 0.16741805 | U25: 546.19953 | V25: 1.3538059 | W25: 29.301282 | X25: 0.10124315 | Y25: 0.40339473 | Z25: 0.00087825333
B26: 241-2025 | C26: usušená surovina živce | D26: 241-2025-3 | E26: 1 | F26: 1.542 | G26: 45665 | I26: =IF($D26="","",_xlfn.xlookup($D26,$R:$R,$S:$S,"")) -> #NAME? | J26: =IF($D26="","",_xlfn.xlookup($D26,$R:$R,$T:$T,"")) -> #NAME? | K26: =IF($D26="","",_xlfn.xlookup($D26,$R:$R,$U:$U,"")) -> #NAME? | L26: =IF($D26="","",_xlfn.xlookup($D26,$R:$R,$V:$V,"")) -> #NAME? | M26: =IF($D26="","",_xlfn.xlookup($D26,$R:$R,$W:$W,"")) -> #NAME? | N26: =IF($D26="","",_xlfn.xlookup($D26,$R:$R,$X:$X,"")) -> #NAME? | O26: =IF($D26="","",_xlfn.xlookup($D26,$R:$R,$Y:$Y,"")) -> #NAME? | P26: =IF($D26="","",_xlfn.xlookup($D26,$R:$R,$Z:$Z,"")) -> #NAME? | R26: 3607-2025-3 | S26: 36.548763 | T26: 0.25167669 | U26: 1019.3279 | V26: 2.5551838 | W26: 25.792646 | X26: 0.1521971 | Y26: 0.5905684 | Z26: 0.0014171556
B27: 563-2025 | C27: beton | D27: 563-2025-4 | E27: 1 | F27: 1.295 | G27: 45716 | I27: =IF($D27="","",_xlfn.xlookup($D27,$R:$R,$S:$S,"")) -> #NAME? | J27: =IF($D27="","",_xlfn.xlookup($D27,$R:$R,$T:$T,"")) -> #NAME? | K27: =IF($D27="","",_xlfn.xlookup($D27,$R:$R,$U:$U,"")) -> #NAME? | L27: =IF($D27="","",_xlfn.xlookup($D27,$R:$R,$V:$V,"")) -> #NAME? | M27: =IF($D27="","",_xlfn.xlookup($D27,$R:$R,$W:$W,"")) -> #NAME? | N27: =IF($D27="","",_xlfn.xlookup($D27,$R:$R,$X:$X,"")) -> #NAME? | O27: =IF($D27="","",_xlfn.xlookup($D27,$R:$R,$Y:$Y,"")) -> #NAME? | P27: =IF($D27="","",_xlfn.xlookup($D27,$R:$R,$Z:$Z,"")) -> #NAME? | R27: 3606-2025-3 | S27: 4.650943 | T27: 0.046585155 | U27: 214.62589 | V27: 0.55655901 | W27: 1.4088889 | X27: 0.028171561 | Y27: 0.09408955 | Z27: 0.00027994918
B28: 628-2025 | C28: cihla | D28: 628-2025-3 | E28: 1 | F28: 1.342 | G28: 45687 | I28: =IF($D28="","",_xlfn.xlookup($D28,$R:$R,$S:$S,"")) -> #NAME? | J28: =IF($D28="","",_xlfn.xlookup($D28,$R:$R,$T:$T,"")) -> #NAME? | K28: =IF($D28="","",_xlfn.xlookup($D28,$R:$R,$U:$U,"")) -> #NAME? | L28: =IF($D28="","",_xlfn.xlookup($D28,$R:$R,$V:$V,"")) -> #NAME? | M28: =IF($D28="","",_xlfn.xlookup($D28,$R:$R,$W:$W,"")) -> #NAME? | N28: =IF($D28="","",_xlfn.xlookup($D28,$R:$R,$X:$X,"")) -> #NAME? | O28: =IF($D28="","",_xlfn.xlookup($D28,$R:$R,$Y:$Y,"")) -> #NAME? | P28: =IF($D28="","",_xlfn.xlookup($D28,$R:$R,$Z:$Z,"")) -> #NAME? | R28: 3549-2025-3 | S28: 205.50489 | T28: 1.2894408 | U28: 2129.1501 | V28: 5.6611521 | W28: 321.8257 | X28: 0.77976686 | Y28: 3.0038615 | Z28: 0.0061021178
B29: 629-2025 | C29: dlažba | D29: 629-2025-3 | E29: 1 | F29: 1.454 | G29: 45687 | I29: =IF($D29="","",_xlfn.xlookup($D29,$R:$R,$S:$S,"")) -> #NAME? | J29: =IF($D29="","",_xlfn.xlookup($D29,$R:$R,$T:$T,"")) -> #NAME? | K29: =IF($D29="","",_xlfn.xlookup($D29,$R:$R,$U:$U,"")) -> #NAME? | L29: =IF($D29="","",_xlfn.xlookup($D29,$R:$R,$V:$V,"")) -> #NAME? | M29: =IF($D29="","",_xlfn.xlookup($D29,$R:$R,$W:$W,"")) -> #NAME? | N29: =IF($D29="","",_xlfn.xlookup($D29,$R:$R,$X:$X,"")) -> #NAME? | O29: =IF($D29="","",_xlfn.xlookup($D29,$R:$R,$Y:$Y,"")) -> #NAME? | P29: =IF($D29="","",_xlfn.xlookup($D29,$R:$R,$Z:$Z,"")) -> #NAME? | R29: 3514-2025-3 | S29: 29.122062 | T29: 0.17600753 | U29: 685.41295 | V29: 1.6088563 | W29: 19.987257 | X29: 0.10643749 | Y29: 0.42548081 | Z29: 0.00095657346
... B55: 2552-2025 | C55: beton C20/25 XC2 | D55: 2552-2025-3 | E55: 1 | F55: 1.445 | G55: 45826 | I55: =IF($D55="","",_xlfn.xlookup($D55,$R:$R,$S:$S,"")) -> #NAME? | J55: =IF($D55="","",_xlfn.xlookup($D55,$R:$R,$T:$T,"")) -> #NAME? | K55: =IF($D55="","",_xlfn.xlookup($D55,$R:$R,$U:$U,"")) -> #NAME? | L55: =IF($D55="","",_xlfn.xlookup($D55,$R:$R,$V:$V,"")) -> #NAME? | M55: =IF($D55="","",_xlfn.xlookup($D55,$R:$R,$W:$W,"")) -> #NAME? | N55: =IF($D55="","",_xlfn.xlookup($D55,$R:$R,$X:$X,"")) -> #NAME? | O55: =IF($D55="","",_xlfn.xlookup($D55,$R:$R,$Y:$Y,"")) -> #NAME? | P55: =IF($D55="","",_xlfn.xlookup($D55,$R:$R,$Z:$Z,"")) -> #NAME? | R55: 2423-2025-3 | S55: 52.424496 | T55: 0.29037164 | U55: 860.89356 | V55: 2.4056424 | W55: 42.93113 | X55: 0.17559719 | Y55: 0.67636849 | Z55: 0.0015332035
B56: 2601-2025 | C56: Amfibolit | D56: 2601-2025-3 | E56: 1 | F56: 2.191 | G56: 45826 | H56: HK | I56: =IF($D56="","",_xlfn.xlookup($D56,$R:$R,$S:$S,"")) -> #NAME? | J56: =IF($D56="","",_xlfn.xlookup($D56,$R:$R,$T:$T,"")) -> #NAME? | K56: =IF($D56="","",_xlfn.xlookup($D56,$R:$R,$U:$U,"")) -> #NAME? | L56: =IF($D56="","",_xlfn.xlookup($D56,$R:$R,$V:$V,"")) -> #NAME? | M56: =IF($D56="","",_xlfn.xlookup($D56,$R:$R,$W:$W,"")) -> #NAME? | N56: =IF($D56="","",_xlfn.xlookup($D56,$R:$R,$X:$X,"")) -> #NAME? | O56: =IF($D56="","",_xlfn.xlookup($D56,$R:$R,$Y:$Y,"")) -> #NAME? | P56: =IF($D56="","",_xlfn.xlookup($D56,$R:$R,$Z:$Z,"")) -> #NAME? | R56: 2422-2025-3 | S56: 66.814849 | T56: 0.29627063 | U56: 351.19492 | V56: 1.4001892 | W56: 33.078133 | X56: 0.1791645 | Y56: 0.5051718 | Z56: 0.0014126665
B57: 2603-2025 | C57: granodiorit | D57: 2603-2025-3 | E57: 1 | F57: 1.899 | G57: 45826 | H57: HK | I57: =IF($D57="","",_xlfn.xlookup($D57,$R:$R,$S:$S,"")) -> #NAME? | J57: =IF($D57="","",_xlfn.xlookup($D57,$R:$R,$T:$T,"")) -> #NAME? | K57: =IF($D57="","",_xlfn.xlookup($D57,$R:$R,$U:$U,"")) -> #NAME? | L57: =IF($D57="","",_xlfn.xlookup($D57,$R:$R,$V:$V,"")) -> #NAME? | M57: =IF($D57="","",_xlfn.xlookup($D57,$R:$R,$W:$W,"")) -> #NAME? | N57: =IF($D57="","",_xlfn.xlookup($D57,$R:$R,$X:$X,"")) -> #NAME? | O57: =IF($D57="","",_xlfn.xlookup($D57,$R:$R,$Y:$Y,"")) -> #NAME? | P57: =IF($D57="","",_xlfn.xlookup($D57,$R:$R,$Z:$Z,"")) -> #NAME? | R57: 2421-2025-3 | S57: 49.51275 | T57: 0.26168463 | U57: 754.16344 | V57: 2.1588241 | W57: 38.698712 | X57: 0.15824922 | Y57: 0.60992387 | Z57: 0.0013801385
B58: 2604-2025 | C58: Rohovec až rula | D58: 2604-2025-3 | E58: 1 | F58: 1.777 | G58: 45826 | H58: HK | I58: =IF($D58="","",_xlfn.xlookup($D58,$R:$R,$S:$S,"")) -> #NAME? | J58: =IF($D58="","",_xlfn.xlookup($D58,$R:$R,$T:$T,"")) -> #NAME? | K58: =IF($D58="","",_xlfn.xlookup($D58,$R:$R,$U:$U,"")) -> #NAME? | L58: =IF($D58="","",_xlfn.xlookup($D58,$R:$R,$V:$V,"")) -> #NAME? | M58: =IF($D58="","",_xlfn.xlookup($D58,$R:$R,$W:$W,"")) -> #NAME? | N58: =IF($D58="","",_xlfn.xlookup($D58,$R:$R,$X:$X,"")) -> #NAME? | O58: =IF($D58="","",_xlfn.xlookup($D58,$R:$R,$Y:$Y,"")) -> #NAME? | P58: =IF($D58="","",_xlfn.xlookup($D58,$R:$R,$Z:$Z,"")) -> #NAME? | R58: 2212-2025-2 | S58: 16.054725 | T58: 0.094959203 | U58: 360.71182 | V58: 0.77169736 | W58: 17.942907 | X58: 0.057424924 | Y58: 0.26346756 | Z58: 0.00049879931
B59: 2605-2025 | C59: Štěrkopísek | D59: 2605-2025-3 | E59: 1 | F59: 1.748 | G59: 45826 | H59: HK | I59: =IF($D59="","",_xlfn.xlookup($D59,$R:$R,$S:$S,"")) -> #NAME? | J59: =IF($D59="","",_xlfn.xlookup($D59,$R:$R,$T:$T,"")) -> #NAME? | K59: =IF($D59="","",_xlfn.xlookup($D59,$R:$R,$U:$U,"")) -> #NAME? | L59: =IF($D59="","",_xlfn.xlookup($D59,$R:$R,$V:$V,"")) -> #NAME? | M59: =IF($D59="","",_xlfn.xlookup($D59,$R:$R,$W:$W,"")) -> #NAME? | N59: =IF($D59="","",_xlfn.xlookup($D59,$R:$R,$X:$X,"")) -> #NAME? | O59: =IF($D59="","",_xlfn.xlookup($D59,$R:$R,$Y:$Y,"")) -> #NAME? | P59: =IF($D59="","",_xlfn.xlookup($D59,$R:$R,$Z:$Z,"")) -> #NAME? | R59: 1753-2025-2 | S59: 38.5043 | T59: 0.18751729 | U59: 800.2318 | V59: 1.9567198 | W59: 38.452097 | X59: 0.11339781 | Y59: 0.58735209 | Z59: 0.0010665789
B60: 2763-2025 | C60: granodiorit, diorit | D60: 2763-2025-3 | E60: 1 | F60: 1.719 | G60: 45831 | H60: HK | I60: =IF($D60="","",_xlfn.xlookup($D60,$R:$R,$S:$S,"")) -> #NAME? | J60: =IF($D60="","",_xlfn.xlookup($D60,$R:$R,$T:$T,"")) -> #NAME? | K60: =IF($D60="","",_xlfn.xlookup($D60,$R:$R,$U:$U,"")) -> #NAME? | L60: =IF($D60="","",_xlfn.xlookup($D60,$R:$R,$V:$V,"")) -> #NAME? | M60: =IF($D60="","",_xlfn.xlookup($D60,$R:$R,$W:$W,"")) -> #NAME? | N60: =IF($D60="","",_xlfn.xlookup($D60,$R:$R,$X:$X,"")) -> #NAME? | O60: =IF($D60="","",_xlfn.xlookup($D60,$R:$R,$Y:$Y,"")) -> #NAME? | P60: =IF($D60="","",_xlfn.xlookup($D60,$R:$R,$Z:$Z,"")) -> #NAME? | R60: 993-2025-3 | S60: 59.498694 | T60: 0.15107546 | U60: 265.16661 | V60: 1.6720744 | W60: 40.927686 | X60: 0.091360255 | Y60: 0.49135628 | Z60: 0.00087915483
B61: 2764-2025 | C61: Droba | D61: 2764-2025-3 | E61: 1 | F61: 1.866 | G61: 45831 | H61: HK | I61: =IF($D61="","",_xlfn.xlookup($D61,$R:$R,$S:$S,"")) -> #NAME? | J61: =IF($D61="","",_xlfn.xlookup($D61,$R:$R,$T:$T,"")) -> #NAME? | K61: =IF($D61="","",_xlfn.xlookup($D61,$R:$R,$U:$U,"")) -> #NAME? | L61: =IF($D61="","",_xlfn.xlookup($D61,$R:$R,$V:$V,"")) -> #NAME? | M61: =IF($D61="","",_xlfn.xlookup($D61,$R:$R,$W:$W,"")) -> #NAME? | N61: =IF($D61="","",_xlfn.xlookup($D61,$R:$R,$X:$X,"")) -> #NAME? | O61: =IF($D61="","",_xlfn.xlookup($D61,$R:$R,$Y:$Y,"")) -> #NAME? | P61: =IF($D61="","",_xlfn.xlookup($D61,$R:$R,$Z:$Z,"")) -> #NAME? | R61: 883-2025-3 | S61: 63.746033 | T61: 0.3238791 | U61: 364.90957 | V61: 1.6500919 | W61: 99.057903 | X61: 0.19586025 | Y61: 0.82941282 | Z61: 0.0015579134
B62: 2765-2025 | C62: Štěrkopísek | D62: 2765-2025-3 | E62: 1 | F62: 1.747 | G62: 45831 | H62: HK | I62: =IF($D62="","",_xlfn.xlookup($D62,$R:$R,$S:$S,"")) -> #NAME? | J62: =IF($D62="","",_xlfn.xlookup($D62,$R:$R,$T:$T,"")) -> #NAME? | K62: =IF($D62="","",_xlfn.xlookup($D62,$R:$R,$U:$U,"")) -> #NAME? | L62: =IF($D62="","",_xlfn.xlookup($D62,$R:$R,$V:$V,"")) -> #NAME? | M62: =IF($D62="","",_xlfn.xlookup($D62,$R:$R,$W:$W,"")) -> #NAME? | N62: =IF($D62="","",_xlfn.xlookup($D62,$R:$R,$X:$X,"")) -> #NAME? | O62: =IF($D62="","",_xlfn.xlookup($D62,$R:$R,$Y:$Y,"")) -> #NAME? | P62: =IF($D62="","",_xlfn.xlookup($D62,$R:$R,$Z:$Z,"")) -> #NAME? | R62: 882-2025-3 | S62: 187.30729 | T62: 0.98699631 | U62: 177.37587 | V62: 2.9510988 | W62: 182.54574 | X62: 0.59686883 | Y62: 1.5962116 | Z62: 0.0045495048
B63: 2766-2025 | C63: Droba | D63: 2766-2025-3 | E63: 1 | F63: 1.887 | G63: 45831 | H63: HK | I63: =IF($D63="","",_xlfn.xlookup($D63,$R:$R,$S:$S,"")) -> #NAME? | J63: =IF($D63="","",_xlfn.xlookup($D63,$R:$R,$T:$T,"")) -> #NAME? | K63: =IF($D63="","",_xlfn.xlookup($D63,$R:$R,$U:$U,"")) -> #NAME? | L63: =IF($D63="","",_xlfn.xlookup($D63,$R:$R,$V:$V,"")) -> #NAME? | M63: =IF($D63="","",_xlfn.xlookup($D63,$R:$R,$W:$W,"")) -> #NAME? | N63: =IF($D63="","",_xlfn.xlookup($D63,$R:$R,$X:$X,"")) -> #NAME? | O63: =IF($D63="","",_xlfn.xlookup($D63,$R:$R,$Y:$Y,"")) -> #NAME? | P63: =IF($D63="","",_xlfn.xlookup($D63,$R:$R,$Z:$Z,"")) -> #NAME? | R63: 744-2025-3 | S63: 70.779882 | T63: 0.18272439 | U63: 285.53946 | V63: 1.8420683 | W63: 53.413694 | X63: 0.11049939 | Y63: 0.59818123 | Z63: 0.0010262831
B64: 2767-2025 | C64: Štěrkopísek | D64: 2767-2025-3 | E64: 1 | F64: 1.721 | G64: 45831 | H64: HK | I64: =IF($D64="","",_xlfn.xlookup($D64,$R:$R,$S:$S,"")) -> #NAME? | J64: =IF($D64="","",_xlfn.xlookup($D64,$R:$R,$T:$T,"")) -> #NAME? | K64: =IF($D64="","",_xlfn.xlookup($D64,$R:$R,$U:$U,"")) -> #NAME? | L64: =IF($D64="","",_xlfn.xlookup($D64,$R:$R,$V:$V,"")) -> #NAME? | M64: =IF($D64="","",_xlfn.xlookup($D64,$R:$R,$W:$W,"")) -> #NAME? | N64: =IF($D64="","",_xlfn.xlookup($D64,$R:$R,$X:$X,"")) -> #NAME? | O64: =IF($D64="","",_xlfn.xlookup($D64,$R:$R,$Y:$Y,"")) -> #NAME? | P64: =IF($D64="","",_xlfn.xlookup($D64,$R:$R,$Z:$Z,"")) -> #NAME? | R64: 725-2025-3 | S64: 40.405287 | T64: 0.18989573 | U64: 884.57106 | V64: 1.7459157 | W64: 42.941983 | X64: 0.11483613 | Y64: 0.64425122 | Z64: 0.0010339467
B65: 2768-2025 | C65: Ortorula | D65: 2768-2025-3 | E65: 1 | F65: 1.585 | G65: 45831 | H65: HK | I65: =IF($D65="","",_xlfn.xlookup($D65,$R:$R,$S:$S,"")) -> #NAME? | J65: =IF($D65="","",_xlfn.xlookup($D65,$R:$R,$T:$T,"")) -> #NAME? | K65: =IF($D65="","",_xlfn.xlookup($D65,$R:$R,$U:$U,"")) -> #NAME? | L65: =IF($D65="","",_xlfn.xlookup($D65,$R:$R,$V:$V,"")) -> #NAME? | M65: =IF($D65="","",_xlfn.xlookup($D65,$R:$R,$W:$W,"")) -> #NAME? | N65: =IF($D65="","",_xlfn.xlookup($D65,$R:$R,$X:$X,"")) -> #NAME? | O65: =IF($D65="","",_xlfn.xlookup($D65,$R:$R,$Y:$Y,"")) -> #NAME? | P65: =IF($D65="","",_xlfn.xlookup($D65,$R:$R,$Z:$Z,"")) -> #NAME? | R65: 724-2025-3 | S65: 61.52093 | T65: 0.41080419 | U65: 1528.8237 | V65: 3.6441988 | W65: 80.025508 | X65: 0.24842668 | Y65: 1.1148052 | Z65: 0.0022121445
B66: 2770-2025 | C66: Lom Budislav | E66: 1 | G66: 45831 | H66: HK | I66: =IF($D66="","",_xlfn.xlookup($D66,$R:$R,$S:$S,"")) | J66: =IF($D66="","",_xlfn.xlookup($D66,$R:$R,$T:$T,"")) | K66: =IF($D66="","",_xlfn.xlookup($D66,$R:$R,$U:$U,"")) | L66: =IF($D66="","",_xlfn.xlookup($D66,$R:$R,$V:$V,"")) | M66: =IF($D66="","",_xlfn.xlookup($D66,$R:$R,$W:$W,"")) | N66: =IF($D66="","",_xlfn.xlookup($D66,$R:$R,$X:$X,"")) | O66: =IF($D66="","",_xlfn.xlookup($D66,$R:$R,$Y:$Y,"")) | P66: =IF($D66="","",_xlfn.xlookup($D66,$R:$R,$Z:$Z,"")) | R66: 723-2025-3 | S66: 25.459546 | T66: 0.15936932 | U66: 529.23556 | V66: 1.5142805 | W66: 24.73339 | X66: 0.09637582 | Y66: 0.38494396 | Z66: 0.00087703862
B67: 2771-2025 | C67: Lom Humperky - Skuteč | E67: 1 | G67: 45832 | H67: HK | I67: =IF($D67="","",_xlfn.xlookup($D67,$R:$R,$S:$S,"")) | J67: =IF($D67="","",_xlfn.xlookup($D67,$R:$R,$T:$T,"")) | K67: =IF($D67="","",_xlfn.xlookup($D67,$R:$R,$U:$U,"")) | L67: =IF($D67="","",_xlfn.xlookup($D67,$R:$R,$V:$V,"")) | M67: =IF($D67="","",_xlfn.xlookup($D67,$R:$R,$W:$W,"")) | N67: =IF($D67="","",_xlfn.xlookup($D67,$R:$R,$X:$X,"")) | O67: =IF($D67="","",_xlfn.xlookup($D67,$R:$R,$Y:$Y,"")) | P67: =IF($D67="","",_xlfn.xlookup($D67,$R:$R,$Z:$Z,"")) | R67: 638-2025-3 | S67: 47.482987 | T67: 0.15283353 | U67: 640.51644 | V67: 1.8215788 | W67: 44.911011 | X67: 0.092423418 | Y67: 0.59633716 | Z67: 0.00091748013
...

Sheet LabSys
A1: Č.vzorku | B1: K-40 | C1: Nejistota | D1: Ra-226 | E1: Nejistota | F1: Th-228 | G1: Nejistota
A2: 2603 | B2: 1010 | C2: 48.4 | D2: 47.9 | E2: 4.301 | F2: 55 | G2: 2.376
A3: 2604 | B3: 1060 | C3: 50.556 | D3: 46.1 | E3: 4.683 | F3: 59.3 | G3: 2.598
A4: 2605 | B4: 527 | C4: 26.388 | D4: 12.2 | E4: 2.272 | F4: 11.2 | G4: 0.631
A5: 2763 | B5: 668 | C5: 32.946 | D5: 10.5 | E5: 2.183 | F5: 17.7 | G5: 0.911
A6: 2764 | B6: 706 | C6: 33.65 | D6: 48.7 | E6: 3.947 | F6: 46.7 | G6: 1.916
A7: 2765 | B7: 220 | C7: 12.237 | D7: <3,56 | F7: 8.61 | G7: 0.521
A8: 2767 | B8: 324 | C8: 16.218 | D8: 9.53 | E8: 2.002 | F8: 13.5 | G8: 0.646
A9: 2901 | B9: 324 | C9: 19.029 | D9: <7,37 | F9: 13.4 | G9: 0.743
A10: 3187 | B10: 1480 | C10: 77.12 | D10: 105 | E10: 7.903 | F10: 207 | G10: 8.802
A11: 3188 | B11: 574 | C11: 28.481 | D11: 29.3 | E11: 3.42 | F11: 24.4 | G11: 1.171
A12: 3345 | B12: 1190 | C12: 56.589 | D12: 116 | E12: 8.356 | F12: 123 | G12: 5.042
A13: 3512 | B13: 285 | C13: 15.479 | D13: 19.1 | E13: 2.491 | F13: 12.1 | G13: 0.659
A14: 3511 | B14: 460 | C14: 23.427 | D14: 42.4 | E14: 3.949 | F14: 27.4 | G14: 1.292
A15: 3513 | B15: 225 | C15: 12.649 | D15: 8.44 | E15: 1.74 | F15: 8.17 | G15: 0.45
A16: 3514 | B16: 403 | C16: 20.778 | D16: 15.6 | E16: 2.37 | F16: 11.1 | G16: 0.624
A17: 3549 | B17: 1390 | C17: 64.73 | D17: 152 | E17: 9.21 | F17: 218 | G17: 8.231
A18: 3606 | B18: 114 | C18: 7.283 | D18: <2,86 | F18: 0.866 | G18: 0.209
A19: 3607 | B19: 597 | C19: 29.443 | D19: 19 | E19: 2.635 | F19: 14.6 | G19: 0.755
A20: 3608 | B20: 334 | C20: 17.427 | D20: 13.4 | E20: 2.351 | F20: 18.3 | G20: 0.897
A21: 59 | B21: 529 | C21: 29.551 | D21: 15.4 | E21: 2.86 | F21: 18.7 | G21: 1.063
A22: 60 | B22: 268 | C22: 13.982 | D22: 25.5 | E22: 2.321 | F22: 15 | G22: 0.738
A23: 145 | B23: 944 | C23: 47.748 | D23: <8,07 | F23: 98.8 | G23: 4.228
A24: 146 | B24: 832 | C24: 42.132 | D24: 26.9 | E24: 3.153 | F24: 126 | G24: 5.184
A25: 230 | B25: 284 | C25: 15.353 | D25: 53.2 | E25: 4.593 | F25: 55.6 | G25: 2.496
A26: 235 | B26: 261 | C26: 14.113 | D26: 86.8 | E26: 5.969 | F26: 78.2 | G26: 3.406
A27: 241 | B27: 2540 | C27: 129.768 | D27: <5,82 | F27: 7.61 | G27: 0.492
A28: 563 | B28: 367 | C28: 22 | D28: 28.8 | E28: 2.26 | F28: 21.2 | G28: 1.27
A29: 628 | B29: 489 | C29: 25.082 | D29: 29.9 | E29: 2.925 | F29: 32.1 | G29: 1.444
A30: 629 | B30: 588 | C30: 33.102 | D30: 52.3 | E30: 5.568 | F30: 48 | G30: 2.363
A31: 630 | B31: 542 | C31: 27.616 | D31: 39.2 | E31: 2.79 | F31: 41.8 | G31: 1.882
A32: 632 | B32: 556 | C32: 28.33 | D32: 36.5 | E32: 3.558 | F32: 38.1 | G32: 1.571
A33: 631 | B33: 661 | C33: 33.779 | D33: 44.8 | E33: 4.089 | F33: 60.9 | G33: 2.704
A34: 633 | B34: 329 | C34: 17.615 | D34: 39.3 | E34: 3.903 | F34: 38.2 | G34: 1.777
A35: 634 | B35: 297 | C35: 19.207 | D35: 30.5 | E35: 4.255 | F35: 29.8 | G35: 1.599
A36: 635 | B36: 566 | C36: 28.813 | D36: 29.8 | E36: 2.877 | F36: 37.3 | G36: 1.667
A37: 638 | B37: 482 | C37: 25.292 | D37: 31.5 | E37: 3.915 | F37: 35.3 | G37: 1.688
A38: 723 | B38: 307 | C38: 15.69 | D38: 14.8 | E38: 1.226 | F38: 14.8 | G38: 0.69
A39: 724 | B39: 903 | C39: 45.554 | D39: 40.3 | E39: 3.427 | F39: 48.7 | G39: 2.157
... A52: 2548 | B52: 409 | C52: 21.103 | D52: 26 | E52: 2.616 | F52: 24.1 | G52: 1.094
...

Sheet data
G1: Labsys | M1: ASS
G2: Ra | I2: K | K2: Th | M2: Ra | O2: K | Q2: Th
A3: Kniha analýz | B3: Popis vzorku | C3: ID měření | D3: Objem [l] | E3: Hmotnost [kg] | F3: Ref. Dat | G3: A | H3: U | I3: A | J3: U | K3: A | L3: U | M3: A | N3: U | O3: A | P3: U | Q3: A | R3: U
A4: 3666-2024 | B4: Struska/škvára | C4: 3666-2024-4 | D4: 1 | E4: 1.011 | F4: 45574 | G4: =IF($A4="","",_xlfn.xlookup(--LEFT($A4,FIND("-",$A4&"-")-1),LabSys!$A:$A,LabSys!$D:$D,"")) -> 51.7 | H4: =IF($A4="","",_xlfn.xlookup(--LEFT($A4,FIND("-",$A4&"-")-1),LabSys!$A:$A,LabSys!$E:$E,"")) -> 3.1 | I4: =IF($A4="","",_xlfn.xlookup(--LEFT($A4,FIND("-",$A4&"-")-1),LabSys!$A:$A,LabSys!$B:$B,"")) -> 143 | J4: =IF($A4="","",_xlfn.xlookup(--LEFT($A4,FIND("-",$A4&"-")-1),LabSys!$A:$A,LabSys!$C:$C,"")) -> 8.58 | K4: =IF($A4="","",_xlfn.xlookup(--LEFT($A4,FIND("-",$A4&"-")-1),LabSys!$A:$A,LabSys!$F:$F,"")) -> 59.7 | L4: =IF($A4="","",_xlfn.xlookup(--LEFT($A4,FIND("-",$A4&"-")-1),LabSys!$A:$A,LabSys!$G:$G,"")) -> 3.58 | M4: 65.266179 | N4: 0.13556479 | O4: 160.72712 | P4: 1.2151718 | Q4: 63.930664 | R4: 0.081980446
A5: 3667-2024 | B5: Popílek | C5: 3667-2024-4 | D5: 1 | E5: 0.926 | F5: 45572 | G5: =IF($A5="","",_xlfn.xlookup(--LEFT($A5,FIND("-",$A5&"-")-1),LabSys!$A:$A,LabSys!$D:$D,"")) -> 64.3 | H5: =IF($A5="","",_xlfn.xlookup(--LEFT($A5,FIND("-",$A5&"-")-1),LabSys!$A:$A,LabSys!$E:$E,"")) -> 3.86 | I5: =IF($A5="","",_xlfn.xlookup(--LEFT($A5,FIND("-",$A5&"-")-1),LabSys!$A:$A,LabSys!$B:$B,"")) -> 170 | J5: =IF($A5="","",_xlfn.xlookup(--LEFT($A5,FIND("-",$A5&"-")-1),LabSys!$A:$A,LabSys!$C:$C,"")) -> 10.17 | K5: =IF($A5="","",_xlfn.xlookup(--LEFT($A5,FIND("-",$A5&"-")-1),LabSys!$A:$A,LabSys!$F:$F,"")) -> 70.7 | L5: =IF($A5="","",_xlfn.xlookup(--LEFT($A5,FIND("-",$A5&"-")-1),LabSys!$A:$A,LabSys!$G:$G,"")) -> 4.24 | M5: 69.417567 | N5: 0.17533443 | O5: 169.0155 | P5: 1.8358342 | Q5: 66.068438 | R5: 0.10603044
A6: 3668-2024 | B6: Litý granulát | C6: 3668-2024-4 | D6: 1 | E6: 0.948 | F6: 45574 | G6: =IF($A6="","",_xlfn.xlookup(--LEFT($A6,FIND("-",$A6&"-")-1),LabSys!$A:$A,LabSys!$D:$D,"")) -> 58.4 | H6: =IF($A6="","",_xlfn.xlookup(--LEFT($A6,FIND("-",$A6&"-")-1),LabSys!$A:$A,LabSys!$E:$E,"")) -> 3.5 | I6: =IF($A6="","",_xlfn.xlookup(--LEFT($A6,FIND("-",$A6&"-")-1),LabSys!$A:$A,LabSys!$B:$B,"")) -> 175 | J6: =IF($A6="","",_xlfn.xlookup(--LEFT($A6,FIND("-",$A6&"-")-1),LabSys!$A:$A,LabSys!$C:$C,"")) -> 10.51 | K6: =IF($A6="","",_xlfn.xlookup(--LEFT($A6,FIND("-",$A6&"-")-1),LabSys!$A:$A,LabSys!$F:$F,"")) -> 58.2 | L6: =IF($A6="","",_xlfn.xlookup(--LEFT($A6,FIND("-",$A6&"-")-1),LabSys!$A:$A,LabSys!$G:$G,"")) -> 3.49 | M6: 63.664718 | N6: 0.15584943 | O6: 182.17377 | P6: 1.7896456 | Q6: 57.198444 | R6: 0.094247228
A7: 3962-2024 | B7: Popílek a směsi s popílkem | C7: 3962-2024-4 | D7: 1 | E7: 0.893 | F7: 45590 | G7: =IF($A7="","",_xlfn.xlookup(--LEFT($A7,FIND("-",$A7&"-")-1),LabSys!$A:$A,LabSys!$D:$D,"")) -> 57.8 | H7: =IF($A7="","",_xlfn.xlookup(--LEFT($A7,FIND("-",$A7&"-")-1),LabSys!$A:$A,LabSys!$E:$E,"")) -> 3.47 | I7: =IF($A7="","",_xlfn.xlookup(--LEFT($A7,FIND("-",$A7&"-")-1),LabSys!$A:$A,LabSys!$B:$B,"")) -> 227 | J7: =IF($A7="","",_xlfn.xlookup(--LEFT($A7,FIND("-",$A7&"-")-1),LabSys!$A:$A,LabSys!$C:$C,"")) -> 13.63 | K7: =IF($A7="","",_xlfn.xlookup(--LEFT($A7,FIND("-",$A7&"-")-1),LabSys!$A:$A,LabSys!$F:$F,"")) -> 59.3 | L7: =IF($A7="","",_xlfn.xlookup(--LEFT($A7,FIND("-",$A7&"-")-1),LabSys!$A:$A,LabSys!$G:$G,"")) -> 3.56 | M7: 65.629116 | N7: 0.18755629 | O7: 239.37392 | P7: 1.7517688 | Q7: 58.184146 | R7: 0.1134214
A8: 3964-2024 | B8: Popílek a směsi s popílkem | C8: 3964-2024-4 | D8: 1 | E8: 0.989 | F8: 45594 | G8: =IF($A8="","",_xlfn.xlookup(--LEFT($A8,FIND("-",$A8&"-")-1),LabSys!$A:$A,LabSys!$D:$D,"")) -> 96.2 | H8: =IF($A8="","",_xlfn.xlookup(--LEFT($A8,FIND("-",$A8&"-")-1),LabSys!$A:$A,LabSys!$E:$E,"")) -> 5.77 | I8: =IF($A8="","",_xlfn.xlookup(--LEFT($A8,FIND("-",$A8&"-")-1),LabSys!$A:$A,LabSys!$B:$B,"")) -> 322 | J8: =IF($A8="","",_xlfn.xlookup(--LEFT($A8,FIND("-",$A8&"-")-1),LabSys!$A:$A,LabSys!$C:$C,"")) -> 19.32 | K8: =IF($A8="","",_xlfn.xlookup(--LEFT($A8,FIND("-",$A8&"-")-1),LabSys!$A:$A,LabSys!$F:$F,"")) -> 86.9 | L8: =IF($A8="","",_xlfn.xlookup(--LEFT($A8,FIND("-",$A8&"-")-1),LabSys!$A:$A,LabSys!$G:$G,"")) -> 5.22 | M8: 115.69007 | N8: 0.25787551 | O8: 351.6837 | P8: 2.3197972 | Q8: 92.471487 | R8: 0.15594572
A9: 4249-2024 | B9: Struska (VEP) | C9: 4249-2024-4 | D9: 1 | E9: 0.676 | F9: 45616 | G9: =IF($A9="","",_xlfn.xlookup(--LEFT($A9,FIND("-",$A9&"-")-1),LabSys!$A:$A,LabSys!$D:$D,"")) -> 71.8 | H9: =IF($A9="","",_xlfn.xlookup(--LEFT($A9,FIND("-",$A9&"-")-1),LabSys!$A:$A,LabSys!$E:$E,"")) -> 4.31 | I9: =IF($A9="","",_xlfn.xlookup(--LEFT($A9,FIND("-",$A9&"-")-1),LabSys!$A:$A,LabSys!$B:$B,"")) -> 169 | J9: =IF($A9="","",_xlfn.xlookup(--LEFT($A9,FIND("-",$A9&"-")-1),LabSys!$A:$A,LabSys!$C:$C,"")) -> 10.12 | K9: =IF($A9="","",_xlfn.xlookup(--LEFT($A9,FIND("-",$A9&"-")-1),LabSys!$A:$A,LabSys!$F:$F,"")) -> 78.7 | L9: =IF($A9="","",_xlfn.xlookup(--LEFT($A9,FIND("-",$A9&"-")-1),LabSys!$A:$A,LabSys!$G:$G,"")) -> 4.72 | M9: 60.938512 | N9: 0.224858 | O9: 130.68243 | P9: 1.6300245 | Q9: 56.652565 | R9: 0.11747843
A10: 4251-2024 | B10: Aglomerát (VEP z popílku) | C10: 4251-2024-4 | D10: 1 | E10: 0.888 | F10: 45617 | G10: =IF($A10="","",_xlfn.xlookup(--LEFT($A10,FIND("-",$A10&"-")-1),LabSys!$A:$A,LabSys!$D:$D,"")) -> 76.3 | H10: =IF($A10="","",_xlfn.xlookup(--LEFT($A10,FIND("-",$A10&"-")-1),LabSys!$A:$A,LabSys!$E:$E,"")) -> 4.58 | I10: =IF($A10="","",_xlfn.xlookup(--LEFT($A10,FIND("-",$A10&"-")-1),LabSys!$A:$A,LabSys!$B:$B,"")) -> 118 | J10: =IF($A10="","",_xlfn.xlookup(--LEFT($A10,FIND("-",$A10&"-")-1),LabSys!$A:$A,LabSys!$C:$C,"")) -> 7.06 | K10: =IF($A10="","",_xlfn.xlookup(--LEFT($A10,FIND("-",$A10&"-")-1),LabSys!$A:$A,LabSys!$F:$F,"")) -> 70.4 | L10: =IF($A10="","",_xlfn.xlookup(--LEFT($A10,FIND("-",$A10&"-")-1),LabSys!$A:$A,LabSys!$G:$G,"")) -> 4.23 | M10: 80.365807 | N10: 0.19767031 | O10: 117.73906 | P10: 1.626496 | Q10: 64.467232 | R10: 0.10327406
A11: 4457-2024 | B11: Stabilizát | C11: 4457-2024-4 | D11: 1 | E11: 1.167 | F11: 45630 | G11: =IF($A11="","",_xlfn.xlookup(--LEFT($A11,FIND("-",$A11&"-")-1),LabSys!$A:$A,LabSys!$D:$D,"")) -> 49.8 | H11: =IF($A11="","",_xlfn.xlookup(--LEFT($A11,FIND("-",$A11&"-")-1),LabSys!$A:$A,LabSys!$E:$E,"")) -> 2.99 | I11: =IF($A11="","",_xlfn.xlookup(--LEFT($A11,FIND("-",$A11&"-")-1),LabSys!$A:$A,LabSys!$B:$B,"")) -> 143 | J11: =IF($A11="","",_xlfn.xlookup(--LEFT($A11,FIND("-",$A11&"-")-1),LabSys!$A:$A,LabSys!$C:$C,"")) -> 8.6 | K11: =IF($A11="","",_xlfn.xlookup(--LEFT($A11,FIND("-",$A11&"-")-1),LabSys!$A:$A,LabSys!$F:$F,"")) -> 53.8 | L11: =IF($A11="","",_xlfn.xlookup(--LEFT($A11,FIND("-",$A11&"-")-1),LabSys!$A:$A,LabSys!$G:$G,"")) -> 3.23 | M11: 72.20866 | N11: 0.1955454 | O11: 176.5784 | P11: 1.2483334 | Q11: 65.051462 | R11: 0.10216388
A12: 4607-2024 | B12: Úletový popílek | C12: 4607-2024-4 | D12: 1 | E12: 0.697 | F12: 45637 | G12: =IF($A12="","",_xlfn.xlookup(--LEFT($A12,FIND("-",$A12&"-")-1),LabSys!$A:$A,LabSys!$D:$D,"")) -> 62.6 | H12: =IF($A12="","",_xlfn.xlookup(--LEFT($A12,FIND("-",$A12&"-")-1),LabSys!$A:$A,LabSys!$E:$E,"")) -> 3.75 | I12: =IF($A12="","",_xlfn.xlookup(--LEFT($A12,FIND("-",$A12&"-")-1),LabSys!$A:$A,LabSys!$B:$B,"")) -> 252 | J12: =IF($A12="","",_xlfn.xlookup(--LEFT($A12,FIND("-",$A12&"-")-1),LabSys!$A:$A,LabSys!$C:$C,"")) -> 15.13 | K12: =IF($A12="","",_xlfn.xlookup(--LEFT($A12,FIND("-",$A12&"-")-1),LabSys!$A:$A,LabSys!$F:$F,"")) -> 59.9 | L12: =IF($A12="","",_xlfn.xlookup(--LEFT($A12,FIND("-",$A12&"-")-1),LabSys!$A:$A,LabSys!$G:$G,"")) -> 3.59 | M12: 56.326647 | N12: 0.17335495 | O12: 195.64359 | P12: 1.1868142 | Q12: 45.903433 | R12: 0.090570345
A13: 4720-2024 | B13: taška | C13: 4720-2024-3 | D13: 1 | E13: 1.369 | F13: 45616 | G13: =IF($A13="","",_xlfn.xlookup(--LEFT($A13,FIND("-",$A13&"-")-1),LabSys!$A:$A,LabSys!$D:$D,"")) -> 34.9 | H13: =IF($A13="","",_xlfn.xlookup(--LEFT($A13,FIND("-",$A13&"-")-1),LabSys!$A:$A,LabSys!$E:$E,"")) -> 3.417 | I13: =IF($A13="","",_xlfn.xlookup(--LEFT($A13,FIND("-",$A13&"-")-1),LabSys!$A:$A,LabSys!$B:$B,"")) -> 572 | J13: =IF($A13="","",_xlfn.xlookup(--LEFT($A13,FIND("-",$A13&"-")-1),LabSys!$A:$A,LabSys!$C:$C,"")) -> 29.106 | K13: =IF($A13="","",_xlfn.xlookup(--LEFT($A13,FIND("-",$A13&"-")-1),LabSys!$A:$A,LabSys!$F:$F,"")) -> 39.4 | L13: =IF($A13="","",_xlfn.xlookup(--LEFT($A13,FIND("-",$A13&"-")-1),LabSys!$A:$A,LabSys!$G:$G,"")) -> 1.784 | M13: 54.921705 | N13: 0.23761629 | O13: 833.5932 | P13: 2.0454831 | Q13: 54.104593 | R13: 0.12414407
A14: 4723-2024 | B14: taška | C14: 4723-2024-3 | D14: 1 | E14: 1.289 | F14: 45616 | G14: =IF($A14="","",_xlfn.xlookup(--LEFT($A14,FIND("-",$A14&"-")-1),LabSys!$A:$A,LabSys!$D:$D,"")) -> 50.7 | H14: =IF($A14="","",_xlfn.xlookup(--LEFT($A14,FIND("-",$A14&"-")-1),LabSys!$A:$A,LabSys!$E:$E,"")) -> 4.699 | I14: =IF($A14="","",_xlfn.xlookup(--LEFT($A14,FIND("-",$A14&"-")-1),LabSys!$A:$A,LabSys!$B:$B,"")) -> 602 | J14: =IF($A14="","",_xlfn.xlookup(--LEFT($A14,FIND("-",$A14&"-")-1),LabSys!$A:$A,LabSys!$C:$C,"")) -> 30.865 | K14: =IF($A14="","",_xlfn.xlookup(--LEFT($A14,FIND("-",$A14&"-")-1),LabSys!$A:$A,LabSys!$F:$F,"")) -> 52 | L14: =IF($A14="","",_xlfn.xlookup(--LEFT($A14,FIND("-",$A14&"-")-1),LabSys!$A:$A,LabSys!$G:$G,"")) -> 2.34 | M14: 78.191888 | N14: 0.25991286 | O14: 840.93573 | P14: 2.1497122 | Q14: 69.256868 | R14: 0.13579305
A15: 4724-2024 | B15: taška | C15: 4724-2024-3 | D15: 1 | E15: 1.331 | F15: 45616 | G15: =IF($A15="","",_xlfn.xlookup(--LEFT($A15,FIND("-",$A15&"-")-1),LabSys!$A:$A,LabSys!$D:$D,"")) -> 63.9 | H15: =IF($A15="","",_xlfn.xlookup(--LEFT($A15,FIND("-",$A15&"-")-1),LabSys!$A:$A,LabSys!$E:$E,"")) -> 6.114 | I15: =IF($A15="","",_xlfn.xlookup(--LEFT($A15,FIND("-",$A15&"-")-1),LabSys!$A:$A,LabSys!$B:$B,"")) -> 556 | J15: =IF($A15="","",_xlfn.xlookup(--LEFT($A15,FIND("-",$A15&"-")-1),LabSys!$A:$A,LabSys!$C:$C,"")) -> 31.584 | K15: =IF($A15="","",_xlfn.xlookup(--LEFT($A15,FIND("-",$A15&"-")-1),LabSys!$A:$A,LabSys!$F:$F,"")) -> 62.5 | L15: =IF($A15="","",_xlfn.xlookup(--LEFT($A15,FIND("-",$A15&"-")-1),LabSys!$A:$A,LabSys!$G:$G,"")) -> 3.025 | M15: 95.500001 | N15: 0.35153688 | O15: 793.49365 | P15: 2.6627145 | Q15: 83.651268 | R15: 0.18366258
... A77: 4301-2025 | B77: škvára | C77: 4301-2025-2 | D77: 1 | E77: 0.765 | F77: 45960 | G77: =IF($A77="","",_xlfn.xlookup(--LEFT($A77,FIND("-",$A77&"-")-1),LabSys!$A:$A,LabSys!$D:$D,"")) -> 141 | H77: =IF($A77="","",_xlfn.xlookup(--LEFT($A77,FIND("-",$A77&"-")-1),LabSys!$A:$A,LabSys!$E:$E,"")) -> 10.968 | I77: =IF($A77="","",_xlfn.xlookup(--LEFT($A77,FIND("-",$A77&"-")-1),LabSys!$A:$A,LabSys!$B:$B,"")) -> 456 | J77: =IF($A77="","",_xlfn.xlookup(--LEFT($A77,FIND("-",$A77&"-")-1),LabSys!$A:$A,LabSys!$C:$C,"")) -> 28.142 | K77: =IF($A77="","",_xlfn.xlookup(--LEFT($A77,FIND("-",$A77&"-")-1),LabSys!$A:$A,LabSys!$F:$F,"")) -> 92.2 | L77: =IF($A77="","",_xlfn.xlookup(--LEFT($A77,FIND("-",$A77&"-")-1),LabSys!$A:$A,LabSys!$G:$G,"")) -> 4.429 | M77: 135.43118 | N77: 0.29532813 | O77: 408.64419 | P77: 2.3377209 | Q77: 79.214719 | R77: 0.15429598

Sheet porovnani
A1: Kniha analýz | B1: Popis vzorku | C1: ID měření | D1: Objem [l] | E1: Hmotnost [kg] | F1: Metoda | G1: Ref. Dat | H1: A_Ra | I1: U_Ra | J1: A_K | K1: U_K | L1: A_Th | M1: U_Th
A2: 3666-2024 | B2: Struska/škvára | C2: 3666-2024-4 | D2: 1 | E2: 1.011 | F2: HPGe | G2: 45574 | H2: 51.7 | I2: 3.1 | J2: 143 | K2: 8.58 | L2: 59.7 | M2: 3.58
A3: 3667-2024 | B3: Popílek | C3: 3667-2024-4 | D3: 1 | E3: 0.926 | F3: HPGe | G3: 45572 | H3: 64.3 | I3: 3.86 | J3: 170 | K3: 10.17 | L3: 70.7 | M3: 4.24
A4: 3668-2024 | B4: Litý granulát | C4: 3668-2024-4 | D4: 1 | E4: 0.948 | F4: HPGe | G4: 45574 | H4: 58.4 | I4: 3.5 | J4: 175 | K4: 10.51 | L4: 58.2 | M4: 3.49
A5: 3962-2024 | B5: Popílek a směsi s popílkem | C5: 3962-2024-4 | D5: 1 | E5: 0.893 | F5: HPGe | G5: 45590 | H5: 57.8 | I5: 3.47 | J5: 227 | K5: 13.63 | L5: 59.3 | M5: 3.56
A6: 3964-2024 | B6: Popílek a směsi s popílkem | C6: 3964-2024-4 | D6: 1 | E6: 0.989 | F6: HPGe | G6: 45594 | H6: 96.2 | I6: 5.77 | J6: 322 | K6: 19.32 | L6: 86.9 | M6: 5.22
A7: 4249-2024 | B7: Struska (VEP) | C7: 4249-2024-4 | D7: 1 | E7: 0.676 | F7: HPGe | G7: 45616 | H7: 71.8 | I7: 4.31 | J7: 169 | K7: 10.12 | L7: 78.7 | M7: 4.72
A8: 4251-2024 | B8: Aglomerát (VEP z popílku) | C8: 4251-2024-4 | D8: 1 | E8: 0.888 | F8: HPGe | G8: 45617 | H8: 76.3 | I8: 4.58 | J8: 118 | K8: 7.06 | L8: 70.4 | M8: 4.23
A9: 4457-2024 | B9: Stabilizát | C9: 4457-2024-4 | D9: 1 | E9: 1.167 | F9: HPGe | G9: 45630 | H9: 49.8 | I9: 2.99 | J9: 143 | K9: 8.6 | L9: 53.8 | M9: 3.23
A10: 4607-2024 | B10: Úletový popílek | C10: 4607-2024-4 | D10: 1 | E10: 0.697 | F10: HPGe | G10: 45637 | H10: 62.6 | I10: 3.75 | J10: 252 | K10: 15.13 | L10: 59.9 | M10: 3.59
A11: 4720-2024 | B11: taška | C11: 4720-2024-3 | D11: 1 | E11: 1.369 | F11: HPGe | G11: 45616 | H11: 34.9 | I11: 3.417 | J11: 572 | K11: 29.106 | L11: 39.4 | M11: 1.784
A12: 4723-2024 | B12: taška | C12: 4723-2024-3 | D12: 1 | E12: 1.289 | F12: HPGe | G12: 45616 | H12: 50.7 | I12: 4.699 | J12: 602 | K12: 30.865 | L12: 52 | M12: 2.34
A13: 4724-2024 | B13: taška | C13: 4724-2024-3 | D13: 1 | E13: 1.331 | F13: HPGe | G13: 45616 | H13: 63.9 | I13: 6.114 | J13: 556 | K13: 31.584 | L13: 62.5 | M13: 3.025
... A149: 4301-2025 | B149: škvára | C149: 4301-2025-2 | D149: 1 | E149: 0.765 | F149: NaI(Tl) | G149: 45960 | H149: 177.03422 | I149: 0.38604985 | J149: 534.17542 | K149: 3.0558443 | L149: 103.54865 | M149: 0.20169409
